def handle_error(error: Exception):
    pass
